<?xml version='1.0'?>
<sdf version='1.4'>
    <model name="my_robot">
        <!-- <static>true</static> -->
        <static>false</static>
        <self_collide>1</self_collide>

        <!-- CHASIS -->
        <link name='chassis'>
            <pose>0 0 .05 0 0 0</pose>
            <inertial>
                <mass>80.0</mass>
            </inertial>
            <!-- <gravity>0</gravity> -->
            <collision name='collision'>
                <geometry>
                    <cylinder>
                        <radius>.5</radius>
                        <length>.1</length>
                    </cylinder>
                </geometry>
            </collision>

            <visual name='visual'>
                <geometry>
                    <cylinder>
                        <radius>.5</radius>
                        <length>.1</length>
                    </cylinder>
                </geometry>
            </visual>
        </link>

        <!-- ARM ONE -->
        <link name='arm1'>
            <pose>0 0 .125 0 0 0</pose>
            <gravity>0</gravity>
            <collision name='collision'>
                <geometry>
                    <cylinder>
                        <radius>.1</radius>
                        <length>.05</length>
                    </cylinder>
                </geometry>
            </collision>

            <visual name='visual'>
                <geometry>
                    <cylinder>
                        <radius>.1</radius>
                        <length>.05</length>
                    </cylinder>
                </geometry>
            </visual>
        </link>

        <!-- ARM TWO -->
        <link name='arm2'>
            <pose>0 0 1.15 0 0 0</pose>
            <inertial>
                <mass>10.0</mass>
            </inertial>
            <gravity>0</gravity>
            <collision name='collision'>
                <geometry>
                    <cylinder>
                        <radius>.05</radius>
                        <length>2.0</length>
                    </cylinder>
                </geometry>
            </collision>

            <visual name='visual'>
                <geometry>
                    <cylinder>
                        <radius>.05</radius>
                        <length>2.0</length>
                    </cylinder>
                </geometry>
            </visual>
        </link>

        <!-- ARM THREE -->
        <link name='arm3'>
            <pose>0 0 2.65 0 0 0</pose>
            <gravity>0</gravity>
            <collision name='collision'>
                <geometry>
                    <cylinder>
                        <radius>.05</radius>
                        <length>1.0</length>
                    </cylinder>
                </geometry>
            </collision>

            <visual name='visual'>
                <geometry>
                    <cylinder>
                        <radius>.05</radius>
                        <length>1.0</length>
                    </cylinder>
                </geometry>
            </visual>
        </link>

        <!-- ARM FOUR -->
        <link name='arm4'>
            <pose>0 0 3.4 0 0 0</pose>
            <gravity>0</gravity>
            <collision name='collision'>
                <geometry>
                    <cylinder>
                        <radius>.05</radius>
                        <length>0.5</length>
                    </cylinder>
                </geometry>
            </collision>

            <visual name='visual'>
                <geometry>
                    <cylinder>
                        <radius>.05</radius>
                        <length>0.5</length>
                    </cylinder>
                </geometry>
            </visual>
        </link>

        <!-- ARM 5 -->
        <link name="arm5">
            <pose> 0 0 3.9 0 0 0</pose>
            <inertial>
                <pose>0 0 -0.5 0 0 0</pose>
                <inertia>
                    <ixx>0.01</ixx>
                    <ixy>0</ixy>
                    <ixz>0</ixz>
                    <iyy>0.01</iyy>
                    <iyz>0</iyz>
                    <izz>0.01</izz>
                </inertia>
                <mass>1</mass>
            </inertial>
            <gravity>0</gravity>
            <collision name="collision">
                <geometry>
                    <box>
                        <size>0.1 0.1 0.5</size>
                    </box>
                </geometry>
            </collision>
            <visual name="visual">
                <geometry>
                    <box>
                        <size>0.1 0.1 0.5</size>
                    </box>
                </geometry>
            </visual>
        </link>

        <!-- PALM -->
        <link name="palm">
            <pose>0.0 0.0 4.2 0 0 0</pose>
            <inertial>
                <inertia>
                    <ixx>0.01</ixx>
                    <ixy>0</ixy>
                    <ixz>0</ixz>
                    <iyy>0.01</iyy>
                    <iyz>0</iyz>
                    <izz>0.01</izz>
                </inertia>
                <mass>0.5</mass>
            </inertial>
            <gravity>0</gravity>
            <collision name="collision">
                <geometry>
                    <box>
                        <size>0.1 0.2 0.1</size>
                    </box>
                </geometry>
            </collision>
            <visual name="visual">
                <geometry>
                    <box>
                        <size>0.1 0.2 0.1</size>
                    </box>
                </geometry>
                <material>
                    <script>Gazebo/Red</script>
                </material>
            </visual>
        </link>

        <!-- left finger -->
        <link name="left_finger">
            <pose>0.1 0.2 4.2 0 0 -0.78539</pose>
            <inertial>
                <inertia>
                    <ixx>0.01</ixx>
                    <ixy>0</ixy>
                    <ixz>0</ixz>
                    <iyy>0.01</iyy>
                    <iyz>0</iyz>
                    <izz>0.01</izz>
                </inertia>
                <mass>0.1</mass>
            </inertial>
            <gravity>0</gravity>
            <collision name="collision">
                <geometry>
                    <box>
                        <size>0.1 0.3 0.1</size>
                    </box>
                </geometry>
            </collision>
            <visual name="visual">
                <geometry>
                    <box>
                        <size>0.1 0.3 0.1</size>
                    </box>
                </geometry>
                <material>
                    <script>Gazebo/Blue</script>
                </material>
            </visual>
        </link>

        <!-- RIGHT FINGER -->
        <link name="right_finger">
            <pose>0.1 -0.2 4.2 0 0 .78539</pose>
            <inertial>
                <inertia>
                    <ixx>0.01</ixx>
                    <ixy>0</ixy>
                    <ixz>0</ixz>
                    <iyy>0.01</iyy>
                    <iyz>0</iyz>
                    <izz>0.01</izz>
                </inertia>
                <mass>0.1</mass>
            </inertial>
            <gravity>0</gravity>
            <collision name="collision">
                <geometry>
                    <box>
                        <size>0.1 0.3 0.1</size>
                    </box>
                </geometry>
            </collision>
            <visual name="visual">
                <geometry>
                    <box>
                        <size>0.1 0.3 0.1</size>
                    </box>
                </geometry>
                <material>
                    <script>Gazebo/Green</script>
                </material>
            </visual>
        </link>

        <!-- JOINT - CHASIS_ARM1_JOINT -->
        <joint type="revolute" name="chasis_arm1_joint">
            <pose>0 0 -0.025 0 0 0</pose>
            <child>arm1</child>
            <parent>chassis</parent>
            <axis>
                <lower>-0.4</lower>
                <upper>0.4</upper>
                <xyz>0 0 1</xyz>
            </axis>
        </joint>

        <!-- JOINT - ARM1_ARM_2_JOINT -->
         <joint type="revolute" name="arm1_arm2_joint">
            <pose>0 0 -1 0 0 0</pose>
            <child>arm2</child>
            <parent>arm1</parent>
            <axis>
                <xyz>1 0 0</xyz>
            </axis>
        </joint>

        <!-- JOINT - ARM2_ARM3_JOINT -->
        <joint type="revolute" name="arm2_arm3_joint">
            <pose>0 0 -0.5 0 0 0</pose>
            <child>arm3</child>
            <parent>arm2</parent>
            <axis>
                <xyz>1 0 0</xyz>
            </axis>
        </joint>
        <!-- JOINT - ARM3_ARM4_JOINT -->
        <joint type="revolute" name="arm3_arm4_joint">
            <pose>0 0 -0.25 0 0 0</pose>
            <child>arm4</child>
            <parent>arm3</parent>
            <axis>
                <xyz>1 0 0</xyz>
            </axis>
        </joint>

        <!-- JOINT - ARM4_ARM5_JOINT -->
        <joint type="revolute" name="arm4_arm5_joint">
            <pose>0 0 -0.25 0 0 0</pose>
            <child>arm5</child>
            <parent>arm4</parent>
            <axis>
                <xyz>0 1 0</xyz>
            </axis>
        </joint>

        <!-- JOINT - ARM5_PALM_JOINT -->
        <joint name="arm5_palm_joint" type="revolute">
            <parent>arm5</parent>
            <child>palm</child>
            <pose>0 0 -0.05 0 0 0</pose>
            <axis>
                <dynamics>
                    <damping>1.0</damping>
                    <friction>.3</friction>
                    <limit>
                        <lower>-1.0</lower>
                        <upper>1.0</upper>
                        <effort>40</effort>
                        <velocity>1.0</velocity>
                    </limit>
                </dynamics>
            <xyz>0 0 1</xyz>
            </axis>
        </joint>

        <joint name="palm_left_finger" type="revolute">
            <pose>0 -0.15 0 0 0 0</pose>
            <child>left_finger</child>
            <parent>palm</parent>
            <axis>
                <limit>
                    <lower>-0.4</lower>
                    <upper>0.4</upper>
                </limit>
                <xyz>0 0 1</xyz>
            </axis>
        </joint>
        <joint name="left_finger_tip" type="revolute">
            <pose>0 0.1 0 0 0 0</pose>
            <child>left_finger_tip</child>
            <parent>left_finger</parent>
            <axis>
                <limit>
                    <lower>-0.4</lower>
                    <upper>0.4</upper>
                </limit>
                <xyz>0 0 1</xyz>
            </axis>
        </joint>
        <joint name="palm_right_finger" type="revolute">
            <pose>0 0.15 0 0 0 0</pose>
            <child>right_finger</child>
            <parent>palm</parent>
            <axis>
                <limit>
                    <lower>-0.4</lower>
                    <upper>0.4</upper>
                </limit>
                <xyz>0 0 1</xyz>
            </axis>
        </joint>
        <joint name="right_finger_tip" type="revolute">
            <pose>0 0.1 0 0 0 0</pose>
            <child>right_finger_tip</child>
            <parent>right_finger</parent>
            <axis>
                <limit>
                    <lower>-0.4</lower>
                    <upper>0.4</upper>
                </limit>
                <xyz>0 0 1</xyz>
            </axis>
        </joint>
        <joint name="palm_riser" type="prismatic">
            <child>palm</child>
            <parent>riser</parent>
            <axis>
                <limit>
                    <lower>0</lower>
                    <upper>0.9</upper>
                </limit>
                <xyz>0 0 1</xyz>
            </axis>
        </joint>

        <plugin name="arm_control" filename="libcontroller.so" />
        <!-- <plugin name="arm_control" filename="libshow_joint_angles.so" /> -->


    </model>
</sdf>